nohup: ignoring input
/home/zel220/anaconda3/envs/dual_teacher_new/lib/python3.8/site-packages/torch/distributed/launch.py:178: FutureWarning: The module torch.distributed.launch is deprecated
and will be removed in future. Use torchrun.
Note that --use_env is set by default in torchrun.
If your script expects `--local_rank` argument to be set, please
change it to read from `os.environ['LOCAL_RANK']` instead. See 
https://pytorch.org/docs/stable/distributed.html#launch-utility for 
further instructions

  warnings.warn(
WARNING:torch.distributed.run:
*****************************************
Setting OMP_NUM_THREADS environment variable for each process to be 1 in default, to avoid your system being overloaded, please further tune the variable for optimal performance in your application as needed. 
*****************************************
Traceback (most recent call last):
  File "tools/train-rescue.py", line 27, in <module>
    from seg_core.model import MiT_SegFormer
ModuleNotFoundError: No module named 'seg_core'
Traceback (most recent call last):
  File "tools/train-rescue.py", line 27, in <module>
    from seg_core.model import MiT_SegFormer
ModuleNotFoundError: No module named 'seg_core'
Traceback (most recent call last):
  File "tools/train-rescue.py", line 27, in <module>
    from seg_core.model import MiT_SegFormer
ModuleNotFoundError: No module named 'seg_core'
Traceback (most recent call last):
  File "tools/train-rescue.py", line 27, in <module>
    from seg_core.model import MiT_SegFormer
ModuleNotFoundError: No module named 'seg_core'
Traceback (most recent call last):
  File "tools/train-rescue.py", line 27, in <module>
    from seg_core.model import MiT_SegFormer
ModuleNotFoundError: No module named 'seg_core'
Traceback (most recent call last):
  File "tools/train-rescue.py", line 27, in <module>
    from seg_core.model import MiT_SegFormer
ModuleNotFoundError: No module named 'seg_core'
Traceback (most recent call last):
  File "tools/train-rescue.py", line 27, in <module>
    from seg_core.model import MiT_SegFormer
ModuleNotFoundError: No module named 'seg_core'
Traceback (most recent call last):
  File "tools/train-rescue.py", line 27, in <module>
    from seg_core.model import MiT_SegFormer
ModuleNotFoundError: No module named 'seg_core'
ERROR:torch.distributed.elastic.multiprocessing.api:failed (exitcode: 1) local_rank: 0 (pid: 2984936) of binary: /home/zel220/anaconda3/envs/dual_teacher_new/bin/python
Traceback (most recent call last):
  File "/home/zel220/anaconda3/envs/dual_teacher_new/lib/python3.8/runpy.py", line 194, in _run_module_as_main
    return _run_code(code, main_globals, None,
  File "/home/zel220/anaconda3/envs/dual_teacher_new/lib/python3.8/runpy.py", line 87, in _run_code
    exec(code, run_globals)
  File "/home/zel220/anaconda3/envs/dual_teacher_new/lib/python3.8/site-packages/torch/distributed/launch.py", line 193, in <module>
    main()
  File "/home/zel220/anaconda3/envs/dual_teacher_new/lib/python3.8/site-packages/torch/distributed/launch.py", line 189, in main
    launch(args)
  File "/home/zel220/anaconda3/envs/dual_teacher_new/lib/python3.8/site-packages/torch/distributed/launch.py", line 174, in launch
    run(args)
  File "/home/zel220/anaconda3/envs/dual_teacher_new/lib/python3.8/site-packages/torch/distributed/run.py", line 710, in run
    elastic_launch(
  File "/home/zel220/anaconda3/envs/dual_teacher_new/lib/python3.8/site-packages/torch/distributed/launcher/api.py", line 131, in __call__
    return launch_agent(self._config, self._entrypoint, list(args))
  File "/home/zel220/anaconda3/envs/dual_teacher_new/lib/python3.8/site-packages/torch/distributed/launcher/api.py", line 259, in launch_agent
    raise ChildFailedError(
torch.distributed.elastic.multiprocessing.errors.ChildFailedError: 
============================================================
tools/train-rescue.py FAILED
------------------------------------------------------------
Failures:
[1]:
  time      : 2025-05-16_00:32:29
  host      : bina01
  rank      : 1 (local_rank: 1)
  exitcode  : 1 (pid: 2984937)
  error_file: <N/A>
  traceback : To enable traceback see: https://pytorch.org/docs/stable/elastic/errors.html
[2]:
  time      : 2025-05-16_00:32:29
  host      : bina01
  rank      : 2 (local_rank: 2)
  exitcode  : 1 (pid: 2984938)
  error_file: <N/A>
  traceback : To enable traceback see: https://pytorch.org/docs/stable/elastic/errors.html
[3]:
  time      : 2025-05-16_00:32:29
  host      : bina01
  rank      : 3 (local_rank: 3)
  exitcode  : 1 (pid: 2984939)
  error_file: <N/A>
  traceback : To enable traceback see: https://pytorch.org/docs/stable/elastic/errors.html
[4]:
  time      : 2025-05-16_00:32:29
  host      : bina01
  rank      : 4 (local_rank: 4)
  exitcode  : 1 (pid: 2984940)
  error_file: <N/A>
  traceback : To enable traceback see: https://pytorch.org/docs/stable/elastic/errors.html
[5]:
  time      : 2025-05-16_00:32:29
  host      : bina01
  rank      : 5 (local_rank: 5)
  exitcode  : 1 (pid: 2984941)
  error_file: <N/A>
  traceback : To enable traceback see: https://pytorch.org/docs/stable/elastic/errors.html
[6]:
  time      : 2025-05-16_00:32:29
  host      : bina01
  rank      : 6 (local_rank: 6)
  exitcode  : 1 (pid: 2984942)
  error_file: <N/A>
  traceback : To enable traceback see: https://pytorch.org/docs/stable/elastic/errors.html
[7]:
  time      : 2025-05-16_00:32:29
  host      : bina01
  rank      : 7 (local_rank: 7)
  exitcode  : 1 (pid: 2984943)
  error_file: <N/A>
  traceback : To enable traceback see: https://pytorch.org/docs/stable/elastic/errors.html
------------------------------------------------------------
Root Cause (first observed failure):
[0]:
  time      : 2025-05-16_00:32:29
  host      : bina01
  rank      : 0 (local_rank: 0)
  exitcode  : 1 (pid: 2984936)
  error_file: <N/A>
  traceback : To enable traceback see: https://pytorch.org/docs/stable/elastic/errors.html
============================================================
